Workbook

Sheet REKAP PEMBELIAN + BAST
A1: REKAP PEMBELIAN PERANGKAT IT
J2: 2024,2025,2026
A3: NO | B3: PERANGKAT | C3: JUMLAH | D3: SATUAN | E3: TYPE UNIT | F3: BULAN | G3: TAHUN | H3: TANGGAL BAST | J3: TOTAL PERANGKAT | K3: JUMLAH | L3: SATUAN
A4: 1 | B4: RAM PC DDR3 | C4: 25 | D4: UNIT | F4: MEI | G4: 2024 | H4: 45442 | J4: RAM PC DDR3 | K4: =SUMIF($B$4:$B$106,J4,$C$4:$C$106) -> 55 | L4: UNIT
A5: =A4+1 -> 2 | B5: FAN PROSESSOR INTEL (HEADSINK) | C5: 30 | D5: UNIT | F5: MEI | G5: 2024 | H5: 45442 | J5: FAN PROSESSOR INTEL (HEADSINK) | K5: =SUMIF($B$4:$B$106,J5,$C$4:$C$106) -> 135 | L5: UNIT
A6: =A5+1 -> 3 | B6: SSD SATA 120GB | C6: 50 | D6: UNIT | F6: MEI | G6: 2024 | H6: 45442 | J6: SSD SATA 120GB | K6: =SUMIF($B$4:$B$106,J6,$C$4:$C$106) -> 100 | L6: UNIT
A7: =A6+1 -> 4 | B7: RAM PC DDR3 | C7: 30 | D7: UNIT | F7: JUNI | G7: 2024 | H7: 45471 | J7: RAM PC DDR4 | K7: =SUMIF($B$4:$B$106,J7,$C$4:$C$106) -> 5 | L7: UNIT
A8: =A7+1 -> 5 | B8: RAM PC DDR4 | C8: 5 | D8: UNIT | F8: JUNI | G8: 2024 | H8: 45471 | J8: SSD SATA 128GB | K8: =SUMIF($B$4:$B$106,J8,$C$4:$C$106) -> 350 | L8: UNIT
A9: =A8+1 -> 6 | B9: SSD SATA 128GB | C9: 50 | D9: UNIT | F9: JUNI | G9: 2024 | H9: 45471 | J9: PSU 500W ATX | K9: =SUMIF($B$4:$B$106,J9,$C$4:$C$106) -> 130 | L9: UNIT
A10: =A9+1 -> 7 | B10: FAN PROSESSOR INTEL (HEADSINK) | C10: 50 | D10: UNIT | F10: JUNI | G10: 2024 | H10: 45471 | J10: MOUSE | K10: =SUMIF($B$4:$B$106,J10,$C$4:$C$106) -> 425 | L10: UNIT
A11: =A10+1 -> 8 | B11: PSU 500W ATX | C11: 20 | D11: UNIT | F11: JUNI | G11: 2024 | H11: 45471 | J11: HEADSET | K11: =SUMIF($B$4:$B$106,J11,$C$4:$C$106) -> 315 | L11: UNIT
A12: =A11+1 -> 9 | B12: MOUSE | C12: 25 | D12: UNIT | F12: JULI | G12: 2024 | H12: 45492 | J12: KABEL VGA | K12: =SUMIF($B$4:$B$106,J12,$C$4:$C$106) -> 75 | L12: UNIT
A13: =A12+1 -> 10 | B13: HEADSET | C13: 25 | D13: UNIT | F13: JULI | G13: 2024 | H13: 45492 | J13: HDD HARDDISK INTERNAL 3.5" | K13: =SUMIF($B$4:$B$106,J13,$C$4:$C$106) -> 5 | L13: UNIT
A14: =A13+1 -> 11 | B14: KABEL VGA | C14: 30 | D14: UNIT | F14: JULI | G14: 2024 | H14: 45492 | J14: LAN CARD PCI EXPRESS GIGABIT NETWORK ADAPTER | K14: =SUMIF($B$4:$B$106,J14,$C$4:$C$106) -> 3 | L14: UNIT
A15: =A14+1 -> 12 | B15: PSU 500W ATX | C15: 30 | D15: UNIT | F15: JULI | G15: 2024 | H15: 45492 | J15: CRIMPING TOOLS TANG RJ45 + KABEL LAN TESTER | K15: =SUMIF($B$4:$B$106,J15,$C$4:$C$106) -> 2 | L15: UNIT
A16: =A15+1 -> 13 | B16: HDD HARDDISK INTERNAL 3.5" | C16: 1 | D16: UNIT | F16: JULI | G16: 2024 | H16: 45492 | J16: KEYBOARD | K16: =SUMIF($B$4:$B$106,J16,$C$4:$C$106) -> 425 | L16: UNIT
... A25: =A24+1 -> 22 | B25: UTP CAT 5 | C25: 1 | D25: ROLL | F25: SEPTEMBER | G25: 2024 | H25: 45558 | J25: CPU | K25: =SUMIF($B$4:$B$106,J25,$C$4:$C$106) -> 275 | L25: UNIT
A26: =A25+1 -> 23 | B26: CCTV | C26: 4 | D26: UNIT | E26: DS-2CD1143G0E-I | F26: OKTOBER | G26: 2024 | H26: 45587 | K26: =SUM(K4:K25) -> 2599
A27: =A26+1 -> 24 | B27: HDD HARDDISK INTERNAL 3.5" | C27: 3 | D27: UNIT | F27: OKTOBER | G27: 2024 | H27: 45587
A28: =A27+1 -> 25 | B28: CCTV | C28: 1 | D28: UNIT | E28: DS-2CD2955FWD-I(S) | F28: OKTOBER | G28: 2024 | H28: 45587 | J28: 2026
A29: =A28+1 -> 26 | B29: NVR | C29: 1 | D29: UNIT | E29: DS-7604NI-E1/4P | F29: OKTOBER | G29: 2024 | H29: 45587 | J29: TOTAL PERANGKAT | K29: JUMLAH | L29: SATUAN
A30: =A29+1 -> 27 | B30: HDD HARDDISK INTERNAL 3.5" | C30: 1 | D30: UNIT | F30: OKTOBER | G30: 2024 | H30: 45587 | J30: MOUSE | K30: =SUMIF($B$64:$B$106,J30,$C$64:$C$106) -> 250 | L30: UNIT
A31: =A30+1 -> 28 | B31: POWER ADAPTOR LENOVO | C31: 1 | D31: UNIT | F31: NOVEMBER | G31: 2024 | H31: 45608 | J31: HEADSET | K31: =SUMIF($B$64:$B$106,J31,$C$64:$C$106) -> 155 | L31: UNIT
A32: =A31+1 -> 29 | B32: MOUSE | C32: 50 | D32: UNIT | F32: FEBRUARI | G32: 2025 | H32: 45709 | J32: KEYBOARD | K32: =SUMIF($B$64:$B$106,J32,$C$64:$C$106) -> 250 | L32: UNIT
A33: =A32+1 -> 30 | B33: HEADSET | C33: 50 | D33: UNIT | F33: FEBRUARI | G33: 2025 | H33: 45709 | J33: MONITOR | K33: =SUMIF($B$64:$B$106,J33,$C$64:$C$106) -> 175 | L33: UNIT
A34: =A33+1 -> 31 | B34: SSD SATA 128GB | C34: 50 | D34: UNIT | F34: FEBRUARI | G34: 2025 | H34: 45709 | J34: CPU | K34: =SUMIF($B$64:$B$106,J34,$C$64:$C$106) -> 175 | L34: UNIT
A35: =A34+1 -> 32 | B35: FAN PROSESSOR INTEL (HEADSINK) | C35: 30 | D35: UNIT | F35: FEBRUARI | G35: 2025 | H35: 45709 | K35: =SUM(K30:K34) -> 1005
A36: =A35+1 -> 33 | B36: UTP CAT 5 | C36: 1 | D36: ROLL | F36: MEI | G36: 2025 | H36: 45784
A37: =A36+1 -> 34 | B37: KEYBOARD | C37: 15 | D37: UNIT | F37: MEI | G37: 2025 | H37: 45784
A38: =A37+1 -> 35 | B38: PSU 500W ATX | C38: 20 | D38: UNIT | F38: MEI | G38: 2025 | H38: 45784
A39: =A38+1 -> 36 | B39: ADAPTOR MONITOR LG | C39: 8 | D39: UNIT | F39: MEI | G39: 2025 | H39: 45784
A40: =A39+1 -> 37 | B40: KABEL VGA | C40: 15 | D40: UNIT | F40: MEI | G40: 2025 | H40: 45784
A41: =A40+1 -> 38 | B41: SSD SATA 128GB | C41: 25 | D41: UNIT | F41: MEI | G41: 2025 | H41: 45787
A42: =A41+1 -> 39 | B42: SSD SATA 128GB | C42: 25 | D42: UNIT | F42: MEI | G42: 2025 | H42: 45787
A43: =A42+1 -> 40 | B43: KABEL VGA | C43: 15 | D43: UNIT | F43: JULI | G43: 2025 | H43: 45860
A44: =A43+1 -> 41 | B44: SSD SATA 120GB | C44: 50 | D44: UNIT | F44: JULI | G44: 2025 | H44: 45855 | I44: Barang Datang/Merek Bukan Sata
A45: =A44+1 -> 42 | B45: PSU 500W ATX | C45: 20 | D45: UNIT | F45: JULI | G45: 2025 | H45: 45855 | I45: Barang Datang
A46: =A45+1 -> 43 | B46: KEYBOARD | C46: 10 | D46: UNIT | F46: JULI | G46: 2025 | H46: 45855 | I46: Barang Datang
A47: =A46+1 -> 44 | B47: MONITOR | C47: 25 | D47: UNIT | F47: JULI | G47: 2025 | H47: 45866 | I47: Barang Datang
A48: =A47+1 -> 45 | B48: CPU | C48: 25 | D48: UNIT | F48: JULI | G48: 2025 | H48: 45866 | I48: Barang Datang
...

Sheet STOCK PERANGKAT
A1: PERANGKAT | C1: STOCK 2022 | G1: STOCK 2023 | K1: STOCK 2024 | O1: STOCK 2025 | T1: STOCK 2026
AD2: TOTAL DARI DATA PINDAH PERANGKAT
B3: JUMLAH AWAL | C3: PENAMBAHAN | D3: KERUSAKAN | E3: PERBAIKAN | F3: TOTAL | G3: PENAMBAHAN | H3: KERUSAKAN | I3: PERBAIKAN | J3: TOTAL | K3: PENAMBAHAN | L3: KERUSAKAN | M3: PERBAIKAN | N3: TOTAL | O3: PENAMBAHAN | P3: KERUSAKAN | Q3: PERBAIKAN | R3: TERJUAL | S3: TOTAL | T3: PENAMBAHAN | U3: KERUSAKAN | V3: PERBAIKAN | W3: TERJUAL | X3: TOTAL | Y3: STOCK OPNAME JUN 26 | Z3: STOCK OPNAME MAR 26 | AA3: STOCK OPNAME DES 25 | AB3: SELISIH | AD3: CPU | AE3: MOUSE | AF3: HEADSET | AG3: KEYBOARD | AH3: MONITOR
A4: MEJA DC | B4: 771 Meja/ 1139 Bilik | C4: 0 | D4: 0 | E4: 0 | F4: 771 Meja/ 1139 Bilik | G4: 15 | H4: 0 | I4: 0 | J4: 786 Meja / 1220 Bilik | K4: 0 | L4: 0 | M4: 0 | N4: 786 Meja / 1220 Bilik | O4: 16 Meja / 80 Bilik | P4: 0 | Q4: 0 | R4: 0 | S4: 802 Meja / 1300 Bilik | T4: 22 Meja/90 Bilik | U4: 2 Bilik | X4: 824 Meja/ 1388 Bilik | AD4: 1048 | AE4: 1026 | AF4: 1021 | AG4: 1063 | AH4: 1060 | AI4: AGENT
A5: KURSI DC | B5: 871 | C5: 0 | D5: 0 | E5: 0 | F5: =B5+C5-D5+E5 -> 871 | G5: 50 | H5: 163 | I5: 119 | J5: =F5+G5-H5+I5 -> 877 | K5: 430 | L5: 163 | M5: 113 | N5: =J5+K5-L5+M5 -> 1257 | O5: 250 | P5: 608 | Q5: 493 | R5: 130 | S5: 1262 | T5: 49 | X5: =S5+T5-U5+V5-W5 -> 1311 | AD5: 18 | AE5: 34 | AF5: 4 | AG5: 25 | AH5: 19 | AI5: MANAGEMENT
A6: PC ALL IN ONE | B6: 100 | C6: 0 | D6: 4 | E6: 0 | F6: =B6+C6-D6+E6 -> 96 | G6: 0 | H6: 0 | I6: 0 | J6: =F6+G6-H6+I6 -> 96 | K6: 0 | L6: 3 | M6: 0 | N6: =J6+K6-L6+M6 -> 93 | O6: 0 | P6: 0 | Q6: 4 | R6: 0 | S6: =N6+O6-P6+Q6-R6 -> 97 | U6: 4 | V6: 1 | X6: =S6+T6-U6+V6-W6 -> 94 | Y6: ='SO JUN26'!S4 -> 94 | Z6: ='SO MAR26'!S4 -> 89 | AA6: ='SO DES25'!S4 -> 100 | AB6: =Y6-X6 -> 0 | AD6: =S8+S6 -> 1200 | AE6: 1153 | AF6: 1073 | AG6: 1144 | AH6: 1041
A7: LCD MONITOR | B7: 987 | C7: 0 | D7: 95 | E7: 0 | F7: =B7+C7-D7+E7 -> 892 | G7: 0 | H7: 1 | I7: 0 | J7: =F7+G7-H7+I7 -> 891 | K7: 150 | L7: 0 | M7: 0 | N7: =J7+K7-L7+M7 -> 1041 | O7: =50+50 -> 100 | P7: 45 | Q7: 0 | R7: 0 | S7: =N7+O7-P7+Q7-R7 -> 1096 | T7: =50+50+25+50 -> 175 | X7: =S7+T7-U7+V7-W7 -> 1271 | Y7: ='SO JUN26'!S8 -> 1176 | Z7: ='SO MAR26'!S8 -> 1125 | AA7: ='SO DES25'!S8 -> 1096 | AB7: =Y7-X7 -> -95 | AD7: =AD6+AD5-AD4 -> 170 | AE7: =AE6+AE5-AE4 -> 161 | AF7: =AF6+AF5-AF4 -> 56 | AG7: =AG6+AG5-AG4 -> 106 | AH7: =AH4+AH5-AH6 -> 38
A8: CPU + MINI CPU | B8: 1137 | C8: 0 | D8: 235 | E8: 0 | F8: =B8+C8-D8+E8 -> 902 | G8: 0 | H8: 138 | I8: 74 | J8: =F8+G8-H8+I8 -> 838 | K8: 150 | L8: 43 | M8: 134 | N8: =J8+K8-L8+M8 -> 1079 | O8: =50+50 -> 100 | P8: =18+26+27 -> 71 | Q8: 202 | R8: 207 | S8: =N8+O8-P8+Q8-R8 -> 1103 | T8: =50+50+25+50 -> 175 | X8: =S8+T8-U8+V8-W8 -> 1278 | Y8: ='SO JUN26'!S2+'SO JUN26'!S3 -> 1202 | Z8: ='SO MAR26'!S3+'SO MAR26'!S2 -> 1143 | AA8: ='SO DES25'!S3+'SO DES25'!S2 -> 1103 | AB8: =Y8-X8 -> -76 | AH8: KELEBIHAN
A9: MOUSE | B9: 1030 | C9: 0 | D9: 69 | E9: 0 | F9: =B9+C9-D9+E9 -> 961 | G9: 160 | H9: 236 | I9: 0 | J9: =F9+G9-H9+I9 -> 885 | K9: 225 | L9: 22 | M9: 15 | N9: =J9+K9-L9+M9 -> 1103 | O9: =50+50+50 -> 150 | P9: 0 | Q9: 96 | R9: 221 | S9: =N9+O9-P9+Q9-R9 -> 1128 | T9: =50+50+50+25+25+50 -> 250 | X9: =S9+T9-U9+V9-W9 -> 1378 | Y9: ='SO JUN26'!S5 -> 1204 | Z9: ='SO MAR26'!S5 -> 1180 | AA9: ='SO DES25'!S5 -> 1128 | AB9: =Y9-X9 -> -174
A10: KEYBOARD | B10: 1205 | C10: 0 | D10: 198 | E10: 0 | F10: =B10+C10-D10+E10 -> 1007 | G10: 158 | H10: 92 | I10: 0 | J10: =F10+G10-H10+I10 -> 1073 | K10: 200 | L10: 144 | M10: 0 | N10: =J10+K10-L10+M10 -> 1129 | O10: =15+60+50 -> 125 | P10: 0 | Q10: 141 | R10: 245 | S10: =N10+O10-P10+Q10-R10 -> 1150 | T10: =50+50+50+25+25 -> 200 | X10: =S10+T10-U10+V10-W10 -> 1350 | Y10: ='SO JUN26'!S7 -> 1246 | Z10: ='SO MAR26'!S7 -> 1218 | AA10: ='SO DES25'!S7 -> 1150 | AB10: =Y10-X10 -> -104
A11: HEADSET | B11: 995 | C11: 0 | D11: 75 | E11: 0 | F11: =B11+C11-D11+E11 -> 920 | G11: 0 | H11: 54 | I11: 2 | J11: =F11+G11-H11+I11 -> 868 | K11: 155 | L11: 0 | M11: 0 | N11: =J11+K11-L11+M11 -> 1023 | O11: 85 | P11: 44 | Q11: 0 | R11: 0 | S11: =N11+O11-P11+Q11-R11 -> 1064 | T11: =50+25+30+50 -> 155 | X11: =S11+T11-U11+V11-W11 -> 1219 | Y11: ='SO JUN26'!S6 -> 1114 | Z11: ='SO MAR26'!S6 -> 1100 | AA11: ='SO DES25'!S6 -> 1064 | AB11: =Y11-X11 -> -105 | AE11: STOCK OPNAME | AF11: TOTAL TAMBAHAN | AG11: SELISIH | AH11: BELUM MASUK
A12: PRINTER | B12: 3 | C12: 0 | D12: 0 | E12: 0 | F12: =B12+C12-D12+E12 -> 3 | G12: 2 | H12: 1 | I12: 0 | J12: =F12+G12-H12+I12 -> 4 | K12: 1 | L12: 0 | M12: 0 | N12: =J12+K12-L12+M12 -> 5 | O12: 0 | P12: 0 | Q12: 0 | R12: 0 | S12: =N12+O12-P12+Q12-R12 -> 5 | T12: 1 | X12: =S12+T12-U12+V12-W12 -> 6 | Y12: 5 | Z12: 5 | AA12: 5 | AB12: =Y12-X12 -> -1 | AD12: CPU | AE12: 1036 | AF12: 1129 | AG12: =AF12+AH12-AE12 -> 93 | AI12: =1036-13 -> 1023
A13: LAPTOP | B13: 66 | C13: 0 | D13: 0 | E13: 0 | F13: =B13+C13-D13+E13 -> 66 | G13: 2 | H13: 0 | I13: 0 | J13: =F13+G13-H13+I13 -> 68 | K13: 11 | L13: 17 | M13: 0 | N13: =J13+K13-L13+M13 -> 62 | O13: 0 | P13: 37 | Q13: 0 | R13: 0 | S13: =N13+O13-P13+Q13-R13 -> 25 | V13: 1 | X13: =S13+T13-U13+V13-W13 -> 26 | Y13: ='SO JUN26'!S9 -> 25 | Z13: ='SO MAR26'!S9 -> 26 | AA13: ='SO DES25'!S9 -> 24 | AB13: =Y13-X13 -> -1 | AD13: MOUSE | AE13: 1106 | AF13: 1203 | AG13: =AF13+AH13-AE13 -> 97
AD14: HEADSET | AE14: 1083 | AF14: 1073 | AG14: =AF14+AH14-AE14 -> -10
AD15: KEYBOARD | AE15: 1128 | AF15: 1204 | AG15: =AF15+AH15-AE15 -> 76
AD16: MONITOR | AE16: 1036 | AF16: 1091 | AG16: =AF16+AH16-AE16 -> 55 | AI16: =1036-16 -> 1020
G17: =198+92+144 -> 434 | H17: 245 | I17: =G17-H17 -> 189 | O17: R. IT laptop rusak | P17: 32 | AD17: PC PUTIH | AE17: 96 | AF17: 93 | AG17: =AF17+AH17-AE17 -> 1127 | AH17: =94+1036 -> 1130
O18: Gudang GA belakang | P18: 3 | AD18: LAPTOP | AE18: 29 | AF18: 79 | AG18: =AF18+AH18-AE18 -> 50
P19: =1062-1096 -> -34
AD20: TOTAL AGENT | AE20: 987 | AF20: 85 | AG20: =AE20+AF20 -> 1072 | AJ20: 22
P21: =54-17 -> 37 | AG21: - | AH21: =991+97 -> 1088 | AJ21: 16
AD22: 1091 | AE22: 1072 | AF22: =AD22-AE22+97 -> 116 | AH22: =1072+16 -> 1088 | AI22: =AH21+50 -> 1138 | AJ22: 13
AD23: 1129 | AE23: =1072+16 -> 1088 | AF23: =AD23-AE23+97 -> 138 | AG23: =AD23-AH23 -> 37 | AH23: =AH22+11+3-10 -> 1092
AD24: 1203 | AE24: 1072 | AF24: =AD24-AE24 -> 131
AD25: 1204 | AE25: 1072 | AF25: =AD25-AE25 -> 132 | AH25: =138-17-10 -> 111
AD26: 1073 | AE26: 1072 | AF26: =AD26-AE26 -> 1
AI28: 1069
AD29: MINI CPU | AI29: 13
AC30: Awal | AD30: 42 | AE30: 14 | AF30: LAPANGAN | AI30: =AI28+AI29 -> 1082
AC31: Saat ini | AD31: =N8-N7 -> 38 | AE31: 12 | AF31: RUSAK
AE32: 3 | AF32: R. JARINGAN [2] , MASJID
AE33: =AD30-AE31-AE30-AE32 -> 13 | AF33: STOCK RUANG IT
AD35: PERANGKAT DIJUAL
AD36: Tanggal | AE36: Nama Perangkat | AF36: Jumlah | AH36: Total
AD37: 45915 | AE37: CPU | AF37: 152 | AH37: CPU | AI37: =SUMIF($AE$37:$AE$40,AH37,$AF$37:$AF$40) -> 207
AD38: 45915 | AE38: Keyboard | AF38: 245 | AH38: Keyboard | AI38: =SUMIF($AE$37:$AE$40,AH38,$AF$37:$AF$40) -> 245
AD39: 45916 | AE39: CPU | AF39: 55 | AH39: Mouse | AI39: =SUMIF($AE$37:$AE$40,AH39,$AF$37:$AF$40) -> 221
AD40: 45916 | AE40: Mouse | AF40: 221 | AI40: =SUMIF($AE$37:$AE$40,AH40,$AF$37:$AF$40) -> 0
AI41: =SUMIF($AE$37:$AE$40,AH41,$AF$37:$AF$40) -> 0
AI42: =SUMIF($AE$37:$AE$40,AH42,$AF$37:$AF$40) -> 0

Sheet LAPTOP 2026
A1: SERAH TERIMA LAPTOP 2026
A4: NO | B4: INVENTARIS | C4: No BAST | D4: BARANG | E4: POSISI | F4: NAMA | G4: JUMLAH | H4: KETERANGAN | I4: TGL SERAH TERIMA
A5: 1 | B5: B.2/0065/2024 | D5: Laptop ROG Flow Z13 GZ301ZE | E5: Director | F5: Ardhianto Wirawan | G5: 1
A6: =A5+1 -> 2 | B6: B.2/0066/2024 | D6: Laptop Asus Vivobook S14 Flip | E6: Manager Business Development and Operational | F6: Andika Artabayu | G6: 1
A7: =A6+1 -> 3 | B7: B.2/0064/2023 | D7: Laptop Asus Vivobook | E7: Secretary | F7: Lia Nawang Sari | G7: 1
A8: =A7+1 -> 4 | B8: B.2/0067/2024 | D8: Laptop Asus Vivobook 14 A1404ZA | E8: Manager Collection | F8: Setiawan Ginanjar | G8: 1
A9: =A8+1 -> 5 | B9: B.2/0068/2024 | D9: Laptop Asus Vivobook 14 A1404ZA | E9: Manager Collection | F9: Andri Lambok Simatupang | G9: 1
A10: =A9+1 -> 6 | B10: B.2/0070/2024 | D10: Laptop Asus Vivobook 14 A1404ZA | E10: Manager Collection | F10: Yolanda Ardha Pradana | G10: 1 | H10: TUKER DENGAN LAPTOP PAK ARI | I10: 45869
A11: =A10+1 -> 7 | E11: Manager Collection | F11: Ari Wicaksono | G11: 0 | H11: LAPTOP DI AMBIL SSS | I11: 45869
A12: =A11+1 -> 8 | B12: B.2/0063/2023 | D12: Laptop Asus M415D | E12: Manager HRD | F12: Dewi Kartika Sari | G12: 1
A13: =A12+1 -> 9 | E13: Manager FAT | F13: Mudayani | G13: 0
A14: =A13+1 -> 10 | B14: B.2/0074/2024 | D14: Laptop Asus Vivobook 14 A1404ZA | E14: Manager Field Collection | F14: Bagus Anggara Putra | G14: 0 | H14: SUDAH ADA DI RUANGAN IT | I14: 46185
A15: =A14+1 -> 11 | B15: B.2/0071/2024 | D15: Laptop Asus Vivobook 14 A1404ZA | E15: Jr. Manager Legal | F15: Mirza Savira | G15: 2 | H15: DITAMBAH LAPTOP M. HEDI
A16: =A15+1 -> 12 | B16: B.2/0072/2024 | D16: Laptop Asus Vivobook 14 A1404ZA | E16: Asst. Manager Collection | F16: Prianto | G16: 1
A17: =A16+1 -> 13 | B17: B.2/0073/2024 | D17: Laptop Asus Vivobook 14 A1404ZA | E17: Asst. Manager Collection | F17: M. Thoriq Ilmi | G17: 1
A18: =A17+1 -> 14 | B18: B.2/0075/2024 | D18: Laptop Asus Vivobook 14 A1404ZA | E18: Supervisor IT | F18: Abdi Arkananta Satya Sancoko | G18: 1
A19: =A18+1 -> 15 | B19: B.2/0077/2025 | D19: Laptop Lenovo Ideapad S130-14 | E19: Staff GA | F19: Annisa' Soraya | G19: 1
A20: =A19+1 -> 16 | B20: B.2/0079/2025 | D20: Laptop Thinkpad | E20: Staff GA | F20: Pandu Adi Samudra | G20: 1
A21: =A20+1 -> 17 | B21: B.2/0078/2025 | D21: Laptop Lenovo Ideapad 330 | E21: Staff Admin | F21: Untuk Semua | G21: 1
A22: =A21+1 -> 18 | B22: B.2/24/2020 | D22: Laptop Thinkpad | E22: Supervisor QA | F22: Hedi Candra Muhammad | G22: 0 | H22: DIBAWA BU MIRZA | I22: 46179
A23: =A22+1 -> 19 | E23: Staff HRD | F23: Abdul Ardiansya Susilo | G23: 0 | H23: LAPTOP DI AMBIL SSS | I23: 45966
A24: =A23+1 -> 20 | B24: B.2/0087/2025 | D24: Laptop Thinkpad | E24: Staff HRD | F24: Retno Indahsari | G24: 1
A25: =A24+1 -> 21 | B25: B.2/0085/2025 | D25: Laptop Thinkpad | E25: Staff HRD | F25: Zhafran Valdano Wahyushahensa | G25: 1 | H25: TUKER DENGAN LAPTOP PAK ABDUL | I25: 45966
A26: =A25+1 -> 22 | B26: B.2/0086/2025 | D26: Laptop Thinkpad | E26: Staff HRD | F26: Zhafran Valdano Wahyushahensa | G26: 1
A27: =A26+1 -> 23 | B27: B.2/20/2020 | D27: Laptop Thinkpad | E27: Staff HRD | F27: Fais Restyafani | G27: 1
A28: =A27+1 -> 24 | B28: B.2/0076/2025 | D28: Laptop Thinkpad | E28: Staff Medis | F28: Sendi Eka Oktaviani | G28: 1
A29: =A28+1 -> 25 | D29: Laptop Dell | E29: Staff QA | F29: Nor Hasanah | G29: 0
A30: =A29+1 -> 26 | D30: Laptop Dell | E30: Staff QA | F30: Mustofa Fajar Afnani | G30: 0
A31: =A30+1 -> 27 | D31: Laptop Dell | E31: Staff QA | F31: Hanif Maulana | G31: 1
A32: =A31+1 -> 28 | D32: Laptop Dell | E32: Staff QA | F32: Depri Lutfi Amin | G32: 0
A33: =A32+1 -> 29 | D33: Laptop Dell | E33: Staff QA | F33: Muh. Muqodam Ali | G33: 0
A34: =A33+1 -> 30 | D34: Laptop Dell | E34: Staff QA | F34: Frendy Ferry Andika | G34: 0
A35: =A34+1 -> 31 | D35: Laptop Thinkpad | E35: Staff QA | F35: Riva Sardiana Rahmadani | G35: 0
A36: =A35+1 -> 32 | B36: B.2/0084/2025 | D36: Laptop Dell | E36: Staff QA | F36: Luluk Yusrin Amalia | G36: 1
A37: =A36+1 -> 33 | B37: B.2/0069/2024 | D37: Laptop Asus Vivobook 14 A1404ZA | E37: Ruangan IT | F37: Ruangan IT | G37: 1 | H37: Digunakan IT
A38: =A37+1 -> 34 | B38: BLURR | D38: Laptop Lenovo | E38: Ruangan IT | F38: Ruangan IT | G38: 1 | H38: Digunakan IT
A39: =A38+1 -> 35 | B39: B.2/0083/2025 | D39: Laptop Dell | E39: Ruangan IT | F39: Ruangan IT | G39: 1 | H39: Digunakan IT [Dari Riska QA]
A40: =A39+1 -> 36 | D40: Laptop Thinkpad, Dell, Lenovo | E40: Ruangan IT | F40: Ruangan IT | G40: 31 | H40: Rusak
A41: =A40+1 -> 37 | D41: Laptop Thinkpad, Dell, Lenovo | E41: Gudang GA Belakang | F41: Gudang GA Belakang | G41: 3 | H41: Rusak
A42: =A41+1 -> 38 | E42: Tidak di tempat | F42: Tidak di tempat | G42: 1 | H42: laptop dibawa ricky sudah resign
...

Sheet LAPTOP 2025
A1: SERAH TERIMA LAPTOP 2025
A4: NO | B4: INVENTARIS | C4: No BAST | D4: BARANG | E4: POSISI | F4: NAMA | G4: JUMLAH | H4: KETERANGAN | I4: TGL SERAH TERIMA
A5: 1 | B5: B.2/0065/2024 | D5: Laptop ROG Flow Z13 GZ301ZE | E5: Director | F5: Ardhianto Wirawan | G5: 1
A6: =A5+1 -> 2 | B6: B.2/0066/2024 | D6: Laptop Asus Vivobook S14 Flip | E6: Manager Business Development and Operational | F6: Andika Artabayu | G6: 1
A7: =A6+1 -> 3 | B7: B.2/0064/2023 | D7: Laptop Asus Vivobook | E7: Secretary | F7: Lia Nawang Sari | G7: 1
A8: =A7+1 -> 4 | B8: B.2/0067/2024 | D8: Laptop Asus Vivobook 14 A1404ZA | E8: Manager Collection | F8: Setiawan Ginanjar | G8: 1
A9: =A8+1 -> 5 | B9: B.2/0068/2024 | D9: Laptop Asus Vivobook 14 A1404ZA | E9: Manager Collection | F9: Andri Lambok Simatupang | G9: 1
A10: =A9+1 -> 6 | B10: B.2/0070/2024 | D10: Laptop Asus Vivobook 14 A1404ZA | E10: Manager Collection | F10: Yolanda Ardha Pradana | G10: 1 | H10: TUKER DENGAN LAPTOP PAK ARI | I10: 45869
A11: =A10+1 -> 7 | E11: Manager Collection | F11: Ari Wicaksono | G11: 0 | H11: LAPTOP DI AMBIL SSS | I11: 45869
A12: =A11+1 -> 8 | B12: B.2/0063/2023 | D12: Laptop Asus M415D | E12: Manager HRD | F12: Dewi Kartika Sari | G12: 1
A13: =A12+1 -> 9 | E13: Manager FAT | F13: Mudayani | G13: 0
A14: =A13+1 -> 10 | B14: B.2/0074/2024 | D14: Laptop Asus Vivobook 14 A1404ZA | E14: Manager Field Collection | F14: Bagus Anggara Putra | G14: 1
A15: =A14+1 -> 11 | B15: B.2/0071/2024 | D15: Laptop Asus Vivobook 14 A1404ZA | E15: Jr. Manager Legal | F15: Mirza Savira | G15: 1
A16: =A15+1 -> 12 | B16: B.2/0072/2024 | D16: Laptop Asus Vivobook 14 A1404ZA | E16: Asst. Manager Collection | F16: Prianto | G16: 1
A17: =A16+1 -> 13 | B17: B.2/0073/2024 | D17: Laptop Asus Vivobook 14 A1404ZA | E17: Asst. Manager Collection | F17: M. Thoriq Ilmi | G17: 1
A18: =A17+1 -> 14 | B18: B.2/0075/2024 | D18: Laptop Asus Vivobook 14 A1404ZA | E18: Supervisor IT | F18: Abdi Arkananta Satya Sancoko | G18: 1
A19: =A18+1 -> 15 | B19: B.2/0077/2025 | D19: Laptop Lenovo Ideapad S130-14 | E19: Staff GA | F19: Annisa' Soraya | G19: 1
A20: =A19+1 -> 16 | B20: B.2/0079/2025 | D20: Laptop Thinkpad | E20: Staff GA | F20: Pandu Adi Samudra | G20: 1
A21: =A20+1 -> 17 | B21: B.2/0078/2025 | D21: Laptop Lenovo Ideapad 330 | E21: Staff Admin | F21: Untuk Semua | G21: 1
A22: =A21+1 -> 18 | B22: B.2/24/2020 | D22: Laptop Thinkpad | E22: Supervisor QA | F22: Hedi Candra Muhammad | G22: 1
A23: =A22+1 -> 19 | E23: Staff HRD | F23: Abdul Ardiansya Susilo | G23: 0 | H23: LAPTOP DI AMBIL SSS | I23: 45966
A24: =A23+1 -> 20 | B24: B.2/0087/2025 | D24: Laptop Thinkpad | E24: Staff HRD | F24: Retno Indahsari | G24: 1
A25: =A24+1 -> 21 | B25: B.2/0085/2025 | D25: Laptop Thinkpad | E25: Staff HRD | F25: Zhafran Valdano Wahyushahensa | G25: 1 | H25: TUKER DENGAN LAPTOP PAK ABDUL | I25: 45966
A26: =A25+1 -> 22 | B26: B.2/0086/2025 | D26: Laptop Thinkpad | E26: Staff HRD | F26: Zhafran Valdano Wahyushahensa | G26: 1
A27: =A26+1 -> 23 | B27: B.2/20/2020 | D27: Laptop Thinkpad | E27: Staff HRD | F27: Fais Restyafani | G27: 1
A28: =A27+1 -> 24 | B28: B.2/0076/2025 | D28: Laptop Thinkpad | E28: Staff Medis | F28: Sendi Eka Oktaviani | G28: 1
A29: =A28+1 -> 25 | D29: Laptop Dell | E29: Staff QA | F29: Nor Hasanah | G29: 0
A30: =A29+1 -> 26 | B30: B.2/0083/2025 | D30: Laptop Dell | E30: Staff QA | F30: Mustofa Fajar Afnani | G30: 1
A31: =A30+1 -> 27 | D31: Laptop Dell | E31: Staff QA | F31: Hanif Maulana | G31: 1
A32: =A31+1 -> 28 | B32: B.2/0084/2025 | D32: Laptop Dell | E32: Staff QA | F32: Depri Lutfi Amin | G32: 1
A33: =A32+1 -> 29 | D33: Laptop Dell | E33: Staff QA | F33: Muh. Muqodam Ali | G33: 0
A34: =A33+1 -> 30 | D34: Laptop Dell | E34: Staff QA | F34: Frendy Ferry Andika | G34: 0
A35: =A34+1 -> 31 | D35: Laptop Thinkpad | E35: Staff QA | F35: Riva Sardiana Rahmadani | G35: 0
A36: =A35+1 -> 32 | D36: Laptop Dell | E36: Staff QA | F36: Luluk Yusrin Amalia | G36: 0
A37: =A36+1 -> 33 | D37: Laptop Thinkpad, Dell, Lenovo | E37: Ruangan IT | F37: Ruangan IT | G37: 32 | H37: Rusak
A38: =A37+1 -> 34 | B38: B.2/0069/2024 | D38: Laptop Asus Vivobook 14 A1404ZA | E38: Ruangan IT | F38: Ruangan IT | G38: 1 | H38: Digunakan IT
A39: =A38+1 -> 35 | D39: Laptop Thinkpad, Dell, Lenovo | E39: Gudang GA Belakang | F39: Gudang GA Belakang | G39: 3 | H39: Rusak
A40: =A39+1 -> 36 | E40: Tidak di tempat | F40: Tidak di tempat | G40: 1 | H40: laptop dibawa ricky sudah resign
A41: =A40+1 -> 37 | E41: Di pondok | F41: Di pondok | G41: 1 | H41: laptop di pinjam pondok
A42: =A41+1 -> 38 | D42: Laptop Thinkpad, Dell, Lenovo | G42: 17 | H42: Tidak terdeteksi tempat dan kondisi
...

Sheet SO JUL25
A1: No Meja | B1: CPU | C1: Mouse | D1: Headset | E1: Keyboard | F1: Monitor | G1: PC Putih | H1: Keterangan | I1: Laptop | J1: Nama
A2: 1 | B2: V | C2: V | D2: V | E2: V | F2: V | L2: CPU | M2: =COUNTIF(B2:B1277,"V") -> 1036
A3: 2 | B3: V | C3: V | D3: V | E3: V | F3: V | L3: MOUSE | M3: =COUNTIF(C2:C1277,"V") -> 1107
A4: 3 | B4: V | C4: V | D4: V | E4: V | F4: V | L4: HEADSET | M4: =COUNTIF(D2:D1277,"V") -> 1083
A5: 4 | B5: V | C5: V | D5: V | E5: V | F5: V | L5: KEYBOARD | M5: =COUNTIF(E2:E1277,"V") -> 1128
A6: 5 | B6: V | C6: V | D6: V | E6: V | F6: V | L6: MONITOR | M6: =COUNTIF(F2:F1277,"V") -> 1035
A7: 6 | B7: V | C7: V | D7: V | E7: V | F7: V | L7: PC PUTIH | M7: =COUNTIF(G2:G1277,"V") -> 96
A8: 7 | B8: V | C8: V | D8: V | E8: V | F8: V | L8: LAPTOP | M8: =COUNTIF(I2:I1277,"V") -> 31
A9: 8 | B9: V | C9: V | D9: V | E9: V | F9: V
A10: 9 | B10: V | C10: V | D10: V | E10: V | F10: V
A11: 10 | B11: V | C11: V | D11: V | E11: V | F11: V
A12: 11 | B12: V | C12: V | D12: V | E12: V | F12: V
A13: 12 | B13: V | C13: V | D13: V | E13: V | F13: V
A14: 13 | B14: V | C14: V | D14: V | E14: V | F14: V
A15: 14 | B15: V | C15: V | D15: V | E15: V | F15: V
A16: 15 | B16: V | C16: V | D16: V | E16: V | F16: V
A17: 16 | B17: V | C17: V | D17: V | E17: V | F17: V
A18: 17 | B18: V | C18: V | D18: V | E18: V | F18: V
A19: 18 | B19: V | C19: V | D19: V | E19: V | F19: V
A20: 19 | B20: V | C20: V | D20: V | E20: V | F20: V
... A40: 39 | B40: V | C40: V | D40: V | E40: V | F40: V
A41: 40 | C41: V | D41: V | E41: V | G41: V
A42: 41 | C42: V | D42: V | E42: V | G42: V
A43: 42 | B43: V | C43: V | D43: V | E43: V | F43: V
A44: 43 | B44: V | C44: V | D44: V | E44: V | F44: V
A45: 44 | B45: V | C45: V | D45: V | E45: V | F45: V
A46: 45 | B46: V | C46: V | D46: V | E46: V | F46: V
A47: 46 | B47: V | C47: V | D47: V | E47: V | F47: V
A48: 47 | B48: V | C48: V | D48: V | E48: V | F48: V
A49: 48 | B49: V | C49: V | D49: V | E49: V | F49: V
A50: 49 | B50: V | C50: V | D50: V | E50: V | F50: V
A51: 50 | B51: V | C51: V | D51: V | E51: V | F51: V
A52: 51 | B52: V | C52: V | D52: V | E52: V | F52: V
A53: 52 | B53: V | C53: V | D53: V | E53: V | F53: V
A54: 53 | C54: V | D54: V | E54: V | G54: V
A55: 54 | B55: V | D55: V | E55: V | F55: V
A56: 55 | B56: V | C56: V | D56: V | E56: V | F56: V
A57: 56 | B57: V | C57: V | D57: V | E57: V | F57: V
A58: 57 | B58: V | C58: V | D58: V | E58: V | F58: V
A59: 58 | B59: V | C59: V | D59: V | E59: V | F59: V
...

Sheet SO OKT25
A1: No Meja | B1: Mini CPU | C1: CPU | D1: Mouse | E1: Headset | F1: Keyboard | G1: Monitor | H1: PC Putih | I1: Laptop | J1: Keterangan | K1: Nama
A2: 1 | C2: V | D2: V | E2: V | F2: V | G2: V | M2: MINI CPU | N2: =COUNTIF(B1:B1285,"V") -> 3
A3: 2 | C3: V | D3: V | E3: V | F3: V | G3: V | M3: CPU | N3: =COUNTIF(C2:C1285,"V") -> 1030
A4: 3 | C4: V | D4: V | E4: V | F4: V | G4: V | M4: MOUSE | N4: =COUNTIF(D2:D1285,"V") -> 1083
A5: 4 | C5: V | D5: V | E5: V | F5: V | G5: V | M5: HEADSET | N5: =COUNTIF(E2:E1285,"V") -> 1054 | O5: 35
A6: 5 | C6: V | D6: V | E6: V | F6: V | G6: V | M6: KEYBOARD | N6: =COUNTIF(F2:F1285,"V") -> 1122
A7: 6 | C7: V | D7: V | E7: V | F7: V | G7: V | M7: MONITOR | N7: =COUNTIF(G2:G1285,"V") -> 1041
A8: 7 | C8: V | D8: V | E8: V | F8: V | G8: V | M8: PC PUTIH | N8: =COUNTIF(H2:H1285,"V") -> 93 | O8: 17 | P8: =N8+O8 -> 110
A9: 8 | C9: V | D9: V | E9: V | F9: V | G9: V | M9: LAPTOP | N9: =COUNTIF(I2:I1285,"V") -> 31
A10: 9 | C10: V | D10: V | E10: V | F10: V | G10: V | M10: MEJA KOSONG | N10: =COUNTIF(J2:J1285,"MEJA KOSONG") -> 90
A11: 10 | C11: V | D11: V | E11: V | F11: V | G11: V | M11: PRIBADI | N11: =COUNTIF(B2:I1285,"PRIBADI") -> 67
A12: 11 | C12: V | D12: V | E12: V | F12: V | G12: V
A13: 12 | C13: V | D13: V | E13: V | F13: V | G13: V
A14: 13 | C14: V | D14: V | E14: V | F14: V | G14: V
A15: 14 | D15: V | E15: V | F15: V | H15: V
A16: 15 | C16: V | D16: V | E16: V | F16: V | G16: V
A17: 16 | C17: V | D17: V | E17: V | F17: V | G17: V
A18: 17 | C18: V | D18: V | F18: V | G18: V
A19: 18 | C19: V | D19: V | F19: V | G19: V
A20: 19 | C20: V | D20: V | E20: V | F20: V | G20: V
A21: 20 | C21: V | D21: V | E21: V | F21: V | G21: V
A22: 21 | C22: V | D22: V | E22: V | F22: V | G22: V
A23: 22 | C23: V | D23: V | E23: V | F23: V | G23: V
A24: 23 | C24: V | D24: V | E24: V | F24: V | G24: V
A25: 24 | C25: V | D25: V | E25: V | F25: V | G25: V
A26: 25 | C26: V | D26: V | E26: V | F26: V | G26: V
A27: 26 | C27: V | D27: V | E27: V | F27: V | G27: V
A28: 27 | C28: V | D28: V | E28: V | F28: V | G28: V
A29: 28 | C29: V | D29: V | E29: V | F29: V | G29: V
A30: 29 | C30: V | D30: V | E30: V | F30: V | G30: V
A31: 30 | C31: V | D31: V | F31: V | G31: V
A32: 31 | C32: V | D32: V | F32: V | G32: V
A33: 32 | C33: V | D33: V | E33: V | F33: V | G33: V
A34: 33 | C34: V | D34: V | E34: V | F34: V | G34: V
A35: 34 | C35: V | D35: V | E35: V | F35: V | G35: V
A36: 35 | C36: V | D36: V | E36: V | F36: V | G36: V
A37: 36 | C37: V | D37: V | E37: V | F37: V | G37: V
A38: 37 | C38: V | D38: V | E38: V | F38: V | G38: V
A39: 38 | C39: V | D39: V | E39: V | F39: V | G39: V
A40: 39 | J40: MEJA KOSONG
...

Sheet SO DES25
A1: No Meja | B1: Mini CPU | C1: CPU | D1: Mouse | E1: Headset | F1: Keyboard | G1: Monitor | H1: PC Putih | I1: Laptop | J1: Keterangan | K1: Nama | S1: TOTAL
A2: 1 | C2: V | D2: V | E2: V | F2: V | G2: V | K2: Lt3 | M2: MINI CPU | N2: =COUNTIF(B1:B1279,"V") -> 5 | O2: =37-18 -> 19 | Q2: 8 | S2: =N2+O2+P2+Q2+R2 -> 32 | T2: 18
A3: =A2+1 -> 2 | C3: V | D3: V | E3: V | F3: V | G3: V | K3: Lt3 | M3: CPU | N3: =COUNTIF(C2:C1279,"V") -> 1043 | O3: 28 | S3: =N3+O3+P3+Q3+R3 -> 1071 | U3: =42-26 -> 16
A4: =A3+1 -> 3 | C4: V | D4: V | E4: V | F4: V | G4: V | K4: Lt3 | M4: PC PUTIH | N4: =COUNTIF(H2:H1279,"V") -> 93 | O4: 5 | Q4: 1 | R4: 1 | S4: =N4+O4+P4+Q4+R4 -> 100
A5: =A4+1 -> 4 | C5: V | D5: V | E5: V | F5: V | G5: V | K5: Lt3 | M5: MOUSE | N5: =COUNTIF(D2:D1279,"V") -> 1097 | P5: 30 | Q5: 1 | S5: =N5+O5+P5+Q5+R5 -> 1128
A6: =A5+1 -> 5 | C6: V | D6: V | E6: V | F6: V | G6: V | K6: Lt3 | M6: HEADSET | N6: =COUNTIF(E2:E1279,"V") -> 1064 | S6: =N6+O6+P6+Q6+R6 -> 1064
A7: =A6+1 -> 6 | C7: V | D7: V | E7: V | F7: V | G7: V | K7: Lt3 | M7: KEYBOARD | N7: =COUNTIF(F2:F1279,"V") -> 1119 | P7: 30 | Q7: 1 | S7: =N7+O7+P7+Q7+R7 -> 1150
A8: =A7+1 -> 7 | C8: V | D8: V | E8: V | F8: V | G8: V | K8: Lt3 | M8: MONITOR | N8: =COUNTIF(G2:G1279,"V") -> 1046 | O8: 18 | P8: 32 | S8: =N8+O8+P8+Q8+R8 -> 1096
A9: =A8+1 -> 8 | C9: V | D9: V | E9: V | F9: V | G9: V | K9: Lt3 | M9: LAPTOP | N9: =COUNTIF(I2:I1279,"V") -> 24 | S9: =N9+O9+P9+Q9+R9 -> 24
A10: =A9+1 -> 9 | C10: V | D10: V | E10: V | F10: V | G10: V | K10: Lt3 | M10: MEJA KOSONG | N10: =COUNTIF(J2:J1279,"MEJA KOSONG") -> 90 | S10: =N10+O10+P10+Q10+R10 -> 90
A11: =A10+1 -> 10 | C11: V | D11: V | E11: V | F11: V | G11: V | K11: Lt3 | M11: PRIBADI | N11: =COUNTIF(B2:I1279,"PRIBADI") -> 43 | S11: =N11+O11+P11+Q11+R11 -> 43
A12: =A11+1 -> 11 | C12: V | D12: V | E12: V | F12: V | G12: V | K12: Lt3
A13: =A12+1 -> 12 | C13: V | D13: V | E13: V | F13: V | G13: V | K13: Lt3 | N13: DC & MANAGEMENT | O13: R. IT | P13: R TRAINING | Q13: R. Meeting Besar | R13: Skyteam | S13: TOTAL
A14: =A13+1 -> 13 | C14: V | D14: V | E14: V | F14: V | G14: V | K14: Lt3
A15: =A14+1 -> 14 | C15: V | D15: V | E15: V | F15: V | G15: V | K15: Lt3 | N15: =N3-17 -> 1026 | O15: cpu
A16: =A15+1 -> 15 | C16: V | D16: V | E16: V | F16: V | G16: V | K16: Lt3 | N16: 93 | O16: pc putih
A17: =A16+1 -> 16 | C17: V | D17: V | E17: V | F17: V | G17: V | K17: Lt3 | N17: 90 | O17: meja kosong
A18: =A17+1 -> 17 | J18: MEJA KOSONG | K18: Lt3 | N18: 3 | O18: mini cpu yang perangkat agak lengkap
A19: =A18+1 -> 18 | C19: V | D19: V | E19: V | F19: V | G19: V | K19: Lt3 | N19: =SUM(N15:N18) -> 1212
A20: =A19+1 -> 19 | C20: V | D20: V | E20: V | F20: V | G20: V | K20: Lt3
A21: =A20+1 -> 20 | C21: V | D21: V | E21: V | F21: V | G21: V | K21: Lt3
A22: =A21+1 -> 21 | C22: V | D22: V | E22: V | F22: V | G22: V | K22: Lt3
A23: =A22+1 -> 22 | C23: V | D23: V | E23: V | F23: V | G23: V | K23: Lt3 | N23: =N3-17 -> 1026 | O23: =N8-17 -> 1029 | P23: =1097-38 -> 1059
A24: =A23+1 -> 23 | C24: V | D24: V | E24: V | F24: V | G24: V | K24: Lt3
A25: =A24+1 -> 24 | C25: V | D25: V | E25: V | F25: V | G25: V | K25: Lt3
A26: =A25+1 -> 25 | C26: V | D26: V | E26: V | F26: V | G26: V | K26: Lt3
A27: =A26+1 -> 26 | C27: V | D27: V | E27: V | F27: V | G27: V | K27: Lt3
A28: =A27+1 -> 27 | C28: V | D28: V | E28: V | F28: V | G28: V | K28: Lt3
A29: =A28+1 -> 28 | C29: V | D29: V | E29: V | F29: V | G29: V | K29: Lt3
A30: =A29+1 -> 29 | C30: V | D30: V | E30: V | F30: V | G30: V | K30: Lt3
A31: =A30+1 -> 30 | C31: V | D31: V | F31: V | G31: V | K31: Lt3
A32: =A31+1 -> 31 | C32: V | D32: V | F32: V | G32: V | K32: Lt3
A33: =A32+1 -> 32 | C33: V | D33: V | F33: V | G33: V | K33: Lt3
A34: =A33+1 -> 33 | C34: V | D34: V | E34: V | F34: V | G34: V | K34: Lt3
A35: =A34+1 -> 34 | C35: V | D35: V | E35: V | F35: V | G35: V | K35: Lt3
A36: =A35+1 -> 35 | C36: V | D36: V | E36: V | F36: V | G36: V | K36: Lt3
A37: =A36+1 -> 36 | C37: V | D37: V | E37: V | F37: V | G37: V | K37: Lt3
A38: =A37+1 -> 37 | C38: V | D38: V | E38: V | F38: V | G38: V | K38: Lt3
A39: =A38+1 -> 38 | C39: V | D39: V | E39: V | F39: V | G39: V | K39: Lt3
A40: =A39+1 -> 39 | J40: MEJA KOSONG | K40: Lt3
...

Sheet SO MAR26
A1: No Meja | B1: Mini CPU | C1: CPU | D1: Mouse | E1: Headset | F1: Keyboard | G1: Monitor | H1: PC Putih | I1: Laptop | J1: Keterangan | K1: Nama | S1: TOTAL
A2: 1 | C2: V | D2: V | E2: V | F2: V | G2: V | K2: LT 3 | M2: MINI CPU | N2: =COUNTIF(B1:B1348,"V") -> 0 | O2: 32 | S2: =N2+O2+P2+Q2+R2 -> 32
A3: =A2+1 -> 2 | C3: V | D3: V | E3: V | F3: V | G3: V | K3: LT 3 | M3: CPU | N3: =COUNTIF(C2:C1348,"V") -> 1109 | P3: 2 | S3: =N3+O3+P3+Q3+R3 -> 1111
A4: =A3+1 -> 3 | C4: V | D4: V | E4: V | F4: V | G4: V | K4: LT 3 | M4: PC PUTIH | N4: =COUNTIF(H2:H1348,"V") -> 54 | O4: 9 | P4: 24 | Q4: 1 | R4: 1 | S4: =N4+O4+P4+Q4+R4 -> 89
A5: =A4+1 -> 4 | C5: V | D5: V | E5: V | F5: V | G5: V | K5: LT 3 | M5: MOUSE | N5: =COUNTIF(D2:D1348,"V") -> 1118 | O5: 1 | P5: 60 | Q5: 1 | S5: =N5+O5+P5+Q5+R5 -> 1180
A6: =A5+1 -> 5 | C6: V | D6: V | E6: V | F6: V | G6: V | K6: LT 3 | M6: HEADSET | N6: =COUNTIF(E2:E1348,"V") -> 1098 | O6: 2 | S6: =N6+O6+P6+Q6+R6 -> 1100
A7: =A6+1 -> 6 | C7: V | D7: V | E7: V | F7: V | G7: V | K7: LT 3 | M7: KEYBOARD | N7: =COUNTIF(F2:F1348,"V") -> 1154 | O7: 1 | P7: 62 | Q7: 1 | S7: =N7+O7+P7+Q7+R7 -> 1218
A8: =A7+1 -> 7 | C8: V | D8: V | E8: V | F8: V | G8: V | K8: LT 3 | M8: MONITOR | N8: =COUNTIF(G2:G1348,"V") -> 1114 | O8: 7 | P8: 4 | S8: =N8+O8+P8+Q8+R8 -> 1125
A9: =A8+1 -> 8 | C9: V | D9: V | E9: V | F9: V | G9: V | K9: LT 3 | M9: LAPTOP | N9: =COUNTIF(I2:I1348,"V") -> 26 | S9: =N9+O9+P9+Q9+R9 -> 26
A10: =A9+1 -> 9 | C10: V | D10: V | F10: V | G10: V | K10: LT 3 | M10: MEJA KOSONG | N10: =COUNTIF(J2:J1348,"MK") -> 131 | S10: =N10+O10+P10+Q10+R10 -> 131
A11: =A10+1 -> 10 | C11: V | D11: V | E11: V | F11: V | G11: V | K11: LT 3 | M11: PRIBADI | N11: =COUNTIF(B2:I1348,"P") -> 72 | S11: =N11+O11+P11+Q11+R11 -> 72
A12: =A11+1 -> 11 | C12: V | D12: V | E12: V | F12: V | G12: V | K12: LT 3
A13: =A12+1 -> 12 | C13: V | D13: V | E13: V | F13: V | G13: V | K13: LT 3 | N13: DC & MANAGEMENT | O13: R. IT | P13: R ECEG | Q13: R. Meeting Besar | R13: Skyteam | S13: TOTAL
A14: =A13+1 -> 13 | C14: V | D14: V | E14: V | F14: V | G14: V | K14: LT 3
A15: =A14+1 -> 14 | C15: V | D15: V | E15: V | F15: V | G15: V | K15: LT 3
A16: =A15+1 -> 15 | J16: MK | K16: LT 3
A17: =A16+1 -> 16 | C17: V | D17: V | E17: V | F17: V | G17: V | K17: LT 3
A18: =A17+1 -> 17 | C18: V | D18: V | E18: V | F18: V | G18: V | K18: LT 3
A19: =A18+1 -> 18 | C19: V | D19: V | F19: V | G19: V | K19: LT 3
A20: =A19+1 -> 19 | C20: V | D20: V | E20: V | F20: V | G20: V | K20: LT 3
A21: =A20+1 -> 20 | C21: V | D21: V | E21: V | F21: V | G21: V | K21: LT 3
A22: =A21+1 -> 21 | C22: V | D22: V | E22: V | F22: V | G22: V | K22: LT 3
A23: =A22+1 -> 22 | C23: V | D23: V | E23: V | F23: V | G23: V | K23: LT 3
A24: =A23+1 -> 23 | C24: V | D24: V | E24: V | F24: V | G24: V | K24: LT 3
A25: =A24+1 -> 24 | C25: V | D25: V | E25: V | F25: V | G25: V | K25: LT 3
A26: =A25+1 -> 25 | C26: V | D26: V | E26: V | F26: V | G26: V | K26: LT 3
A27: =A26+1 -> 26 | C27: V | D27: V | E27: V | F27: V | G27: V | K27: LT 3
A28: =A27+1 -> 27 | C28: V | D28: V | E28: V | F28: V | G28: V | K28: LT 3
A29: =A28+1 -> 28 | C29: V | D29: V | E29: V | F29: V | G29: V | K29: LT 3
A30: =A29+1 -> 29 | C30: V | D30: V | E30: V | F30: V | G30: V | K30: LT 3
A31: =A30+1 -> 30 | C31: V | D31: V | E31: V | F31: V | G31: V | K31: LT 3
A32: =A31+1 -> 31 | C32: V | D32: V | F32: V | G32: V | K32: LT 3
A33: =A32+1 -> 32 | C33: V | D33: V | E33: V | F33: V | G33: V | K33: LT 3
A34: =A33+1 -> 33 | C34: V | D34: V | E34: V | F34: V | G34: V | K34: LT 3
A35: =A34+1 -> 34 | C35: V | D35: V | E35: V | F35: V | G35: V | K35: LT 3
A36: =A35+1 -> 35 | C36: V | D36: V | E36: V | F36: V | G36: V | K36: LT 3
A37: =A36+1 -> 36 | C37: V | D37: V | E37: V | F37: V | G37: V | K37: LT 3
A38: =A37+1 -> 37 | C38: V | D38: V | E38: V | F38: V | G38: V | K38: LT 3
A39: =A38+1 -> 38 | C39: V | D39: V | F39: V | G39: V | K39: LT 3
A40: =A39+1 -> 39 | C40: V | D40: V | E40: V | F40: V | G40: V | K40: LT 3
...

Sheet SO JUN26
A1: No Meja | B1: Mini CPU | C1: CPU | D1: Mouse | E1: Headset | F1: Keyboard | G1: Monitor | H1: PC Putih | I1: Laptop | J1: Keterangan | K1: Nama | N1: DC & MANAGEMENT | O1: R. IT | P1: R ECEG | Q1: R. Meeting Besar | R1: Skyteam | S1: TOTAL
A2: 1 | D2: V | E2: V | F2: V | H2: V | K2: LT 3 | M2: MINI CPU | N2: =COUNTIF(B2:B1414,"V") -> 0 | O2: 32 | S2: =N2+O2+P2+Q2+R2 -> 32
A3: =A2+1 -> 2 | D3: V | E3: V | F3: V | H3: V | K3: LT 3 | M3: CPU | N3: =COUNTIF(C2:C1414,"V") -> 1143 | O3: =2+25 -> 27 | S3: =N3+O3+P3+Q3+R3 -> 1170
A4: =A3+1 -> 3 | C4: V | E4: V | F4: V | G4: V | K4: LT 3 | M4: PC PUTIH | N4: =COUNTIF(H2:H1414,"V") -> 87 | O4: 6 | R4: 1 | S4: =N4+O4+P4+Q4+R4 -> 94
A5: =A4+1 -> 4 | C5: V | D5: V | E5: V | F5: V | G5: V | K5: LT 3 | M5: MOUSE | N5: =COUNTIF(D2:D1414,"V") -> 1179 | O5: 25 | S5: =N5+O5+P5+Q5+R5 -> 1204
A6: =A5+1 -> 5 | C6: V | D6: V | E6: V | F6: V | G6: V | K6: LT 3 | M6: HEADSET | N6: =COUNTIF(E2:E1414,"V") -> 1114 | S6: =N6+O6+P6+Q6+R6 -> 1114
A7: =A6+1 -> 6 | C7: V | D7: V | E7: V | F7: V | G7: V | K7: LT 3 | M7: KEYBOARD | N7: =COUNTIF(F2:F1414,"V") -> 1221 | O7: 25 | S7: =N7+O7+P7+Q7+R7 -> 1246
A8: =A7+1 -> 7 | C8: V | D8: V | E8: V | F8: V | G8: V | K8: LT 3 | M8: MONITOR | N8: =COUNTIF(G2:G1414,"V") -> 1144 | O8: =7+25 -> 32 | S8: =N8+O8+P8+Q8+R8 -> 1176
A9: =A8+1 -> 8 | C9: V | D9: V | E9: V | F9: V | G9: V | K9: LT 3 | M9: LAPTOP | N9: =COUNTIF(I2:I1414,"V") -> 22 | O9: 3 | S9: =N9+O9+P9+Q9+R9 -> 25
A10: =A9+1 -> 9 | J10: MK | K10: LT 3 | M10: KUBIKEL KOSONG | N10: =COUNTIF(J2:J1414,"MK") -> 130 | S10: =N10+O10+P10+Q10+R10 -> 130
A11: =A10+1 -> 10 | C11: V | D11: V | E11: V | F11: V | G11: V | K11: LT 3 | M11: KUBIKEL AKTIF | N11: =COUNTBLANK(J2:J1349) -> 1207 | S11: =N11+O11+P11+Q11+R11 -> 1207
A12: =A11+1 -> 11 | C12: V | D12: V | E12: V | F12: V | G12: V | K12: LT 3 | M12: KUBIKEL HILANG | N12: =COUNTIF(J2:J1414,"X") -> 11 | S12: =N12+O12+P12+Q12+R12 -> 11
A13: =A12+1 -> 12 | C13: V | D13: V | E13: V | F13: V | G13: V | K13: LT 3 | M13: PRIBADI | N13: =COUNTIF(B2:I1414,"P") -> 51 | S13: =N13+O13+P13+Q13+R13 -> 51
A14: =A13+1 -> 13 | J14: MK | K14: LT 3 | S14: =N14+O14+P14+Q14+R14 -> 0
A15: =A14+1 -> 14 | J15: MK | K15: LT 3
A16: =A15+1 -> 15 | C16: V | D16: V | E16: V | F16: V | G16: V | K16: LT 3
A17: =A16+1 -> 16 | C17: V | D17: V | E17: V | F17: V | G17: V | K17: LT 3
A18: =A17+1 -> 17 | C18: V | D18: V | E18: V | F18: V | G18: V | K18: LT 3
A19: =A18+1 -> 18 | C19: V | D19: V | E19: V | F19: V | G19: V | K19: LT 3
A20: =A19+1 -> 19 | C20: V | D20: V | E20: V | F20: V | G20: V | K20: LT 3
A21: =A20+1 -> 20 | C21: V | D21: V | E21: V | F21: V | G21: V | K21: LT 3
A22: =A21+1 -> 21 | C22: V | D22: V | E22: V | F22: V | G22: V | K22: LT 3
A23: =A22+1 -> 22 | C23: V | D23: V | E23: V | F23: V | G23: V | K23: LT 3
A24: =A23+1 -> 23 | C24: V | D24: V | E24: V | F24: V | G24: V | K24: LT 3
A25: =A24+1 -> 24 | C25: V | D25: V | E25: V | F25: V | G25: V | K25: LT 3
A26: =A25+1 -> 25 | C26: V | D26: V | E26: V | F26: V | G26: V | K26: LT 3
A27: =A26+1 -> 26 | C27: V | D27: V | E27: V | F27: V | G27: V | K27: LT 3
... A31: =A30+1 -> 30 | C31: V | D31: V | E31: V | F31: V | G31: V | K31: LT 3
A32: =A31+1 -> 31 | C32: V | D32: V | F32: V | G32: V | K32: LT 3
A33: =A32+1 -> 32 | J33: MK | K33: LT 3
A34: =A33+1 -> 33 | C34: V | D34: V | E34: V | F34: V | G34: V | K34: LT 3
A35: =A34+1 -> 34 | C35: V | D35: V | E35: V | F35: V | G35: V | K35: LT 3
A36: =A35+1 -> 35 | C36: V | D36: V | E36: V | F36: V | G36: V | K36: LT 3
A37: =A36+1 -> 36 | C37: V | D37: V | E37: V | F37: V | G37: V | K37: LT 3
A38: =A37+1 -> 37 | C38: V | D38: V | E38: V | F38: V | G38: V | K38: LT 3
A39: =A38+1 -> 38 | J39: MK | K39: LT 3
A40: =A39+1 -> 39 | C40: V | D40: V | E40: V | F40: V | G40: V | K40: LT 3
A41: =A40+1 -> 40 | C41: V | D41: V | E41: V | F41: V | G41: V | K41: LT 3
A42: =A41+1 -> 41 | C42: V | D42: V | E42: V | F42: V | G42: V | K42: LT 3
A43: =A42+1 -> 42 | C43: V | D43: V | E43: V | F43: V | G43: V | K43: LT 3
...

Sheet INVENTARIS - MANAGEMENT
A1: CPU | B1: Mouse | C1: Keyboard | D1: Monitor | E1: PC Putih | F1: Laptop | G1: Nama | H1: Posisi
F2: B.2/0065/2024 | G2: Ardhianto Wirawan | H2: Director
F3: B.2/0066/2024 | G3: Andika Artabayu | H3: Manager Business Development and Operational
G4: M. Dwiki Prabowo | H4: Personal Assistant of Director
B5: V | F5: B.2/0064/2023 | G5: Lia Nawang Sari | H5: Secretary
B6: V | F6: B.2/0067/2024 | G6: Setiawan Ginanjar | H6: Manager Collection
B7: V | F7: B.2/0068/2024 | G7: Andri Lambok Simatupang | H7: Manager Collection
B8: V | F8: B.2/0069/2024 | G8: Yolanda Ardha Pradana | H8: Manager Collection
B9: V | F9: B.2/0070/2024 | G9: Ari Wicaksono | H9: Manager Collection
A10: PC/1398/2025 | B10: MS/1433/2022 | C10: KB/0792/2025 | D10: MN/0829/2025 | F10: B.2/0063/2023 | G10: Dewi Kartika Sari | H10: Manager HRD
A11: PC/1399/2025 | B11: MS/1131/2023 | C11: KB/0816/2025 | D11: MN/108/2020 | G11: Mudayani | H11: Manager FAT
B12: V | F12: B.2/0074/2024 | G12: Bagus Anggara Putra | H12: Manager Field Collection
F13: B.2/0071/2024 | G13: Mirza Savira | H13: Jr. Manager Legal
B14: V | F14: B.2/0072/2024 | G14: Prianto | H14: Asst. Manager Collection
B15: V | F15: B.2/0073/2024 | G15: M. Thoriq Ilmi | H15: Asst. Manager Collection
F16: B.2/0075/2024 | G16: Abdi Arkananta Satya Sancoko | H16: Supervisor IT
A17: PC/1271/2025 | B17: MS/1388/2022 | C17: KB/0480/2025 | D17: MN/0363/2025 | G17: Resya Guesmel | H17: Supervisor QA
G18: Hedi Candra Muhammad | H18: Supervisor QA
G19: Awang Putra Pratama | H19: Supervisor IT
B20: MS/1393/2022 | F20: B.2/0085/2025 | G20: Abdul Ardiansya Susilo | H20: Staff HRD
A21: PC/1269/2025 | B21: MS/1747/2025 | C21: KB/0478/2025 | D21: MN/0361/2025 | G21: Anindita Maharani | H21: Staff Admin
A22: PC/1265/2025 | B22: MS/1378/2022 | C22: 116 | D22: MN/0357/2025 | G22: Annisa' Soraya | H22: Staff GA
B23: MS/0384/2019 | F23: B.2/0087/2025 | G23: Retno Indahsari | H23: Staff HRD
A24: PC/1268/2025 | B24: MS/1746/2025 | C24: KB/0477/2025 | D24: MN/0360/2025 | G24: Novia Natasha Hariyanto | H24: Staff Admin
A25: PC/1273/2025 | B25: MS/1749/2025 | D25: MN/0365/2025 | G25: Norman Arias | H25: Staff Admin
B26: MS/1456/2022 | F26: B.2/0086/2025 | G26: Zhafran Valdano Wahyushahensa | H26: Staff HRD
G27: Depri Lutfi Amin | H27: Staff QA
G28: Harum Maulana | H28: Staff QA
G29: M. Saiful Bahri | H29: Staff QA
B30: MS/1150/2023 | F30: B.2/0080/2025 | G30: Nor Hasanah | H30: Staff QA
G31: Yani Pranata | H31: Staff QA
B32: MS/1386/2025 | F32: B.2/220/06/2019 | G32: Fanny Setiana Liswanto | H32: Staff QA
G33: Mushtofa Fajar Afnani | H33: Staff QA
B34: MS/1444/2022 | F34: B.2/0082/2025 | G34: Muh. Muqodam Ali | H34: Staff QA
A35: PC/1270/2025 | B35: MS/1418/2022 | C35: KB/0479/2025 | D35: MN/0362/2025 | G35: Yusi Pratiwi Angguntari | H35: Staff Admin
B36: MS/0940/2023 | F36: B.2/20/2020 | G36: Fais Restyafani | H36: Staff HRD
B37: MS/1469/2023 | F37: B.2/0084/2025 | G37: Frendy Ferry Andika | H37: Staff QA
G38: Nur Andika | H38: Staff QA
B39: MS/2099/2025 | F39: B.2/0081/2025 | G39: Riva Sardiana Rahmadani | H39: Staff QA
G40: Hanif Maulana | H40: Staff QA
...

Sheet INVENTARIS - AGENT
A1: No Meja | B1: CPU | C1: Mouse | D1: Headset | E1: Keyboard | F1: Monitor | G1: Keterangan
A2: 1 | B2: PC/0558/2021 | C2: MS/0566/2019 | D2: HD/1158/2025 | E2: B8/280/139/2019 | F2: MN/0256/2025
A3: =A2+1 -> 2 | B3: PC/0200/2020 | C3: MS/1594/2025 | D3: HD/1159/2025 | E3: KB/0348/2025 | F3: MN/0298/2019
A4: =A3+1 -> 3 | B4: PC/0284/2021 | C4: MS/0235/2019 | D4: HD/1160/2025 | E4: KB/0234/2025 | F4: MN/0257/2025
A5: =A4+1 -> 4 | B5: PC/1190/2025 | C5: MS/0315/2019 | D5: HD/1100/2022 | E5: KB/0325/2025 | F5: MN/0258/2025
A6: =A5+1 -> 5 | B6: PC/0879/2021 | C6: MS/1141/2023 | D6: HD/1161/2025 | E6: KB/0326/2025 | F6: MN/0259/2025
A7: =A6+1 -> 6 | B7: PC/0906/2020 | C7: MS/0928/2023 | D7: HD/1162/2025 | E7: KB/0415/2019 | F7: MN/0261/2025
A8: =A7+1 -> 7 | B8: PC/0382/2021 | C8: MS/1902/2025 | D8: HD/1163/2025 | E8: KB/0327/2025 | F8: MN/0260/2025
A9: =A8+1 -> 8 | B9: PC/0576/2021 | C9: MS/1153/2023 | D9: HD/1165/2025 | E9: KB/0328/2025 | F9: MN/0010/2019
A10: =A9+1 -> 9 | B10: PC/0612/2021 | C10: MS/1596/2025 | D10: HD/1164/2025 | E10: KB/0329/2025 | F10: MN/0183/2019
A11: =A10+1 -> 10 | B11: PC/0618/2021 | C11: MS/0329/2019 | D11: HD/1166/2025 | E11: KB/0103/2019 | F11: MN/0086/2020
A12: =A11+1 -> 11 | B12: PC/0385/2021 | C12: MS/1597/2025 | D12: HD/1167/2025 | E12: KB/0330/2025 | F12: MN/0262/2025
A13: =A12+1 -> 12 | B13: PC/0640/2020 | C13: MS/1598/2025 | D13: HD/1168/2025 | E13: KB/0331/2025 | F13: MN/0263/2025
A14: =A13+1 -> 13 | B14: PC/0332/2021 | C14: MS/0355/2019 | D14: HD/1091/2022 | E14: KB/0332/2025 | F14: MN/0264/2025
... A26: =A25+1 -> 25 | B26: PC/1193/2025 | C26: MS/1604/2025 | D26: HD/1176/2025 | E26: KB/0340/2025 | F26: MN/0270/2025
A27: =A26+1 -> 26 | B27: - | C27: - | D27: - | E27: - | F27: - | G27: KOSONG
A28: =A27+1 -> 27 | B28: PC/0177/2021 | C28: MS/1605/2025 | D28: HD/1177/2025 | E28: KB/0341/2025 | F28: MN/0195/2019
A29: =A28+1 -> 28 | B29: PC/0204/2021 | C29: MS/1164/2023 | D29: HD/1178/2025 | E29: KB/0342/2025 | F29: MN/0271/2025
A30: =A29+1 -> 29 | B30: PC/0360/2021 | C30: MS/0291/2019 | D30: HD/1179/2025 | E30: KB/0347/2025 | F30: MN/0281/2019
A31: =A30+1 -> 30 | B31: PC/1194/2025 | C31: MS/1606/2025 | D31: X | E31: KB/0343/2025 | F31: MN/0272/2025
A32: =A31+1 -> 31 | B32: PC/1195/2025 | C32: MS/1146/2023 | D32: X | E32: KB/0344/2025 | F32: MN/0273/2025
A33: =A32+1 -> 32 | B33: PC/0394/2021 | C33: MS/0576/2019 | D33: HD/1180/2025 | E33: KB/0345/2025 | F33: MN/0101/2019
A34: =A33+1 -> 33 | B34: PC/1196/2025 | C34: MS/0193/2019 | D34: HD/1182/2025 | E34: KB/0438/2019 | F34: MN/0274/2025
A35: =A34+1 -> 34 | B35: PC/0341/2021 | C35: MS/1607/2025 | D35: HD/1183/2025 | E35: KB/0346/2025 | F35: MN/0275/2025
A36: =A35+1 -> 35 | B36: PC/0895/2020 | C36: MS/0107/2019 | D36: HD/1185/2025 | E36: KB/0249/2019 | F36: MN/0068/2019
A37: =A36+1 -> 36 | B37: PC/0502/2021 | C37: MS/0587/2019 | D37: HD/1184/2025 | E37: KB/0092/2020 | F37: MN/0276/2025
A38: =A37+1 -> 37 | B38: PC/0523/2021 | C38: MS/0854/2023 | D38: HD/0290/2023 | E38: KB/0399/2025 | F38: MN/0122/2020
A39: =A38+1 -> 38 | B39: PC/0562/2021 | C39: MS/0002/2019 | D39: HD/1181/2025 | E39: KB/0400/2025 | F39: MN/0277/2025
... A41: =A40+1 -> 40 | B41: PC/0400/2021 | C41: MS/0221/2019 | D41: HD/1068/2025 | E41: KB/0401/2025 | F41: MN/0098/2019
A42: =A41+1 -> 41 | B42: B3/230/63/2019 | C42: MS/1519/2025 | D42: HD/1069/2025 | E42: KB/1025/2019 | F42: MN/0181/2025 | G42: PUTIH
A43: =A42+1 -> 42 | B43: PC/0218/2021 | C43: PRIBADI | D43: X | E43: KB/0402/2025 | F43: MN/0182/2025
A44: =A43+1 -> 43 | B44: PC/0301/2021 | C44: MS/0003/2019 | D44: HD/1504/2025 | E44: KB/0549/2025 | F44: MN/0313/2019
A45: =A44+1 -> 44 | B45: PC/0313/2021 | C45: MS/1865/2025 | D45: HD/1469/2025 | E45: KB/0550/2025 | F45: MN/0410/2025
A46: =A45+1 -> 45 | B46: PC/0128/2021 | C46: 586 | D46: HD/1451/2025 | E46: B8/280/138/2019 | F46: MN/0118/2019
A47: =A46+1 -> 46 | B47: PC/0378/2021 | C47: MS/1866/2025 | D47: HD/1097/2022 | E47: KB/0551/2025 | F47: MN/0097/2019
A48: =A47+1 -> 47 | B48: PC/0335/2019 | C48: MS/0068/2019 | D48: HD/1075/2025 | E48: KB/0409/2025 | F48: MN/0188/2025
A49: =A48+1 -> 48 | B49: - | C49: - | D49: - | E49: - | F49: - | G49: KOSONG
A50: =A49+1 -> 49 | B50: PC/0572/2021 | C50: MS/1167/2023 | D50: X | E50: KB/0408/2025 | F50: MN/0187/2025
A51: =A50+1 -> 50 | B51: PC/0764/2020 | C51: MS/1523/2025 | D51: HD/1074/2025 | E51: KB/0406/2025 | F51: MN/0186/2025
A52: =A51+1 -> 51 | B52: B3/230/56/2019 | C52: MS/1522/2025 | D52: HD/1073/2025 | E52: KB/0407/2025 | F52: MN/0185/2025
...

Sheet MONITOR - NO INV
B1: NOMOR INVENTARIS TERAKHIR = MN/0180/2021
A3: NO | B3: NAMA ASET | C3: NO INVENTARIS | D3: STIKER TERTEMPEL | E3: STIKER BLM TERTEMPEL | F3: KETERANGAN | H3: KODE | I3: NOMOR | J3: TAHUN
A4: 1 | B4: Monitor | C4: =H4&"/"&I4&"/"&J4 -> MN/0181/2025 | D4: TRUE | E4: FALSE | H4: MN | I4: 0181 | J4: 2025
A5: =A4+1 -> 2 | B5: Monitor | C5: =H5&"/"&I5&"/"&J5 -> MN/0182/2025 | D5: TRUE | E5: FALSE | H5: MN | I5: 0182 | J5: 2025
A6: =A5+1 -> 3 | B6: Monitor | C6: =H6&"/"&I6&"/"&J6 -> MN/0183/2025 | D6: TRUE | E6: FALSE | H6: MN | I6: 0183 | J6: 2025
A7: =A6+1 -> 4 | B7: Monitor | C7: =H7&"/"&I7&"/"&J7 -> MN/0184/2025 | D7: TRUE | E7: FALSE | H7: MN | I7: 0184 | J7: 2025
A8: =A7+1 -> 5 | B8: Monitor | C8: =H8&"/"&I8&"/"&J8 -> MN/0185/2025 | D8: TRUE | E8: FALSE | H8: MN | I8: 0185 | J8: 2025
A9: =A8+1 -> 6 | B9: Monitor | C9: =H9&"/"&I9&"/"&J9 -> MN/0186/2025 | D9: TRUE | E9: FALSE | H9: MN | I9: 0186 | J9: 2025
A10: =A9+1 -> 7 | B10: Monitor | C10: =H10&"/"&I10&"/"&J10 -> MN/0187/2025 | D10: TRUE | E10: FALSE | H10: MN | I10: 0187 | J10: 2025
A11: =A10+1 -> 8 | B11: Monitor | C11: =H11&"/"&I11&"/"&J11 -> MN/0188/2025 | D11: TRUE | E11: FALSE | H11: MN | I11: 0188 | J11: 2025
A12: =A11+1 -> 9 | B12: Monitor | C12: =H12&"/"&I12&"/"&J12 -> MN/0189/2025 | D12: TRUE | E12: FALSE | H12: MN | I12: 0189 | J12: 2025
A13: =A12+1 -> 10 | B13: Monitor | C13: =H13&"/"&I13&"/"&J13 -> MN/0190/2025 | D13: TRUE | E13: FALSE | H13: MN | I13: 0190 | J13: 2025
A14: =A13+1 -> 11 | B14: Monitor | C14: =H14&"/"&I14&"/"&J14 -> MN/0191/2025 | D14: TRUE | E14: FALSE | H14: MN | I14: 0191 | J14: 2025
A15: =A14+1 -> 12 | B15: Monitor | C15: =H15&"/"&I15&"/"&J15 -> MN/0192/2025 | D15: TRUE | E15: FALSE | H15: MN | I15: 0192 | J15: 2025
A16: =A15+1 -> 13 | B16: Monitor | C16: =H16&"/"&I16&"/"&J16 -> MN/0193/2025 | D16: TRUE | E16: FALSE | H16: MN | I16: 0193 | J16: 2025
... A178: =A177+1 -> 175 | B178: Monitor | C178: =H178&"/"&I178&"/"&J178 -> MN/0355/2025 | D178: TRUE | E178: FALSE | H178: MN | I178: 0355 | J178: 2025
A179: =A178+1 -> 176 | B179: Monitor | C179: =H179&"/"&I179&"/"&J179 -> MN/0356/2025 | D179: TRUE | E179: FALSE | H179: MN | I179: 0356 | J179: 2025 | K179: DITEMPEL MANAGEMENT
A180: =A179+1 -> 177 | B180: Monitor | C180: =H180&"/"&I180&"/"&J180 -> MN/0357/2025 | D180: TRUE | E180: FALSE | H180: MN | I180: 0357 | J180: 2025
A181: =A180+1 -> 178 | B181: Monitor | C181: =H181&"/"&I181&"/"&J181 -> MN/0358/2025 | D181: TRUE | E181: FALSE | H181: MN | I181: 0358 | J181: 2025
A182: =A181+1 -> 179 | B182: Monitor | C182: =H182&"/"&I182&"/"&J182 -> MN/0359/2025 | D182: TRUE | E182: FALSE | H182: MN | I182: 0359 | J182: 2025
A183: =A182+1 -> 180 | B183: Monitor | C183: =H183&"/"&I183&"/"&J183 -> MN/0360/2025 | D183: TRUE | E183: FALSE | H183: MN | I183: 0360 | J183: 2025
A184: =A183+1 -> 181 | B184: Monitor | C184: =H184&"/"&I184&"/"&J184 -> MN/0361/2025 | D184: TRUE | E184: FALSE | H184: MN | I184: 0361 | J184: 2025
A185: =A184+1 -> 182 | B185: Monitor | C185: =H185&"/"&I185&"/"&J185 -> MN/0362/2025 | D185: TRUE | E185: FALSE | H185: MN | I185: 0362 | J185: 2025
A186: =A185+1 -> 183 | B186: Monitor | C186: =H186&"/"&I186&"/"&J186 -> MN/0363/2025 | D186: TRUE | E186: FALSE | H186: MN | I186: 0363 | J186: 2025
A187: =A186+1 -> 184 | B187: Monitor | C187: =H187&"/"&I187&"/"&J187 -> MN/0364/2025 | D187: TRUE | E187: FALSE | H187: MN | I187: 0364 | J187: 2025
A188: =A187+1 -> 185 | B188: Monitor | C188: =H188&"/"&I188&"/"&J188 -> MN/0365/2025 | D188: TRUE | E188: FALSE | H188: MN | I188: 0365 | J188: 2025
A189: =A188+1 -> 186 | B189: Monitor | C189: =H189&"/"&I189&"/"&J189 -> MN/0366/2025 | D189: TRUE | E189: FALSE | F189: 29/02/2025 | H189: MN | I189: 0366 | J189: 2025
A190: =A189+1 -> 187 | B190: Monitor | C190: =H190&"/"&I190&"/"&J190 -> MN/0367/2025 | D190: TRUE | E190: FALSE | F190: 29/02/2025 | H190: MN | I190: 0367 | J190: 2025
A191: =A190+1 -> 188 | B191: Monitor | C191: =H191&"/"&I191&"/"&J191 -> MN/0368/2025 | D191: TRUE | E191: FALSE | H191: MN | I191: 0368 | J191: 2025
A192: =A191+1 -> 189 | B192: Monitor | C192: =H192&"/"&I192&"/"&J192 -> MN/0369/2025 | D192: TRUE | E192: FALSE | F192: 29/02/2025 | H192: MN | I192: 0369 | J192: 2025
A193: =A192+1 -> 190 | B193: Monitor | C193: =H193&"/"&I193&"/"&J193 -> MN/0370/2025 | D193: TRUE | E193: FALSE | F193: 29/02/2025 | H193: MN | I193: 0370 | J193: 2025
A194: =A193+1 -> 191 | B194: Monitor | C194: =H194&"/"&I194&"/"&J194 -> MN/0371/2025 | D194: TRUE | E194: FALSE | F194: 29/02/2025 | H194: MN | I194: 0371 | J194: 2025
A195: =A194+1 -> 192 | B195: Monitor | C195: =H195&"/"&I195&"/"&J195 -> MN/0372/2025 | D195: TRUE | E195: FALSE | F195: 29/02/2025 | H195: MN | I195: 0372 | J195: 2025
A196: =A195+1 -> 193 | B196: Monitor | C196: =H196&"/"&I196&"/"&J196 -> MN/0373/2025 | D196: TRUE | E196: FALSE | F196: 29/02/2025 | H196: MN | I196: 0373 | J196: 2025
A197: =A196+1 -> 194 | B197: Monitor | C197: =H197&"/"&I197&"/"&J197 -> MN/0374/2025 | D197: TRUE | E197: FALSE | F197: 29/02/2025 | H197: MN | I197: 0374 | J197: 2025
A198: =A197+1 -> 195 | B198: Monitor | C198: =H198&"/"&I198&"/"&J198 -> MN/0375/2025 | D198: TRUE | E198: FALSE | F198: 29/02/2025 | H198: MN | I198: 0375 | J198: 2025
A199: =A198+1 -> 196 | B199: Monitor | C199: =H199&"/"&I199&"/"&J199 -> MN/0376/2025 | D199: TRUE | E199: FALSE | F199: 29/02/2025 | H199: MN | I199: 0376 | J199: 2025
A200: =A199+1 -> 197 | B200: Monitor | C200: =H200&"/"&I200&"/"&J200 -> MN/0377/2025 | D200: TRUE | E200: FALSE | F200: 29/02/2025 | H200: MN | I200: 0377 | J200: 2025
A201: =A200+1 -> 198 | B201: Monitor | C201: =H201&"/"&I201&"/"&J201 -> MN/0378/2025 | D201: TRUE | E201: FALSE | F201: 29/02/2025 | H201: MN | I201: 0378 | J201: 2025
A202: =A201+1 -> 199 | B202: Monitor | C202: =H202&"/"&I202&"/"&J202 -> MN/0379/2025 | D202: TRUE | E202: FALSE | F202: 29/02/2025 | H202: MN | I202: 0379 | J202: 2025
...

Sheet MONITOR - INVENTARIS
A1: NO | B1: NAMA ASET | C1: NO INVENTARIS | D1: TERPAKAI | E1: RUSAK | F1: PERBAIKI | G1: KETERANGAN
A2: 1 | B2: Monitor | C2: 9 | D2: TRUE | E2: FALSE | F2: FALSE
A3: =A2+1 -> 2 | B3: Monitor | C3: 20 | D3: TRUE | E3: FALSE | F3: FALSE
A4: =A3+1 -> 3 | B4: Monitor | C4: 21 | D4: TRUE | E4: FALSE | F4: FALSE
A5: =A4+1 -> 4 | B5: Monitor | C5: 28 | D5: TRUE | E5: FALSE | F5: FALSE
A6: =A5+1 -> 5 | B6: Monitor | C6: 33 | D6: TRUE | E6: FALSE | F6: FALSE
A7: =A6+1 -> 6 | B7: Monitor | C7: 35 | D7: TRUE | E7: FALSE | F7: FALSE
A8: =A7+1 -> 7 | B8: Monitor | C8: 44 | D8: TRUE | E8: FALSE | F8: FALSE
A9: =A8+1 -> 8 | B9: Monitor | C9: 47 | D9: TRUE | E9: FALSE | F9: FALSE
A10: =A9+1 -> 9 | B10: Monitor | C10: 49 | D10: TRUE | E10: FALSE | F10: FALSE
A11: =A10+1 -> 10 | B11: Monitor | C11: 54 | D11: TRUE | E11: FALSE | F11: FALSE
A12: =A11+1 -> 11 | B12: Monitor | C12: 62 | D12: TRUE | E12: FALSE | F12: FALSE
A13: =A12+1 -> 12 | B13: Monitor | C13: 72 | D13: TRUE | E13: FALSE | F13: FALSE
A14: =A13+1 -> 13 | B14: Monitor | C14: 80 | D14: TRUE | E14: FALSE | F14: FALSE
... A177: =A176+1 -> 176 | B177: Monitor | C177: 966 | D177: TRUE | E177: FALSE | F177: FALSE
A178: =A177+1 -> 177 | B178: Monitor | C178: B.3/203/102/2019 | D178: TRUE | E178: FALSE | F178: FALSE
A179: =A178+1 -> 178 | B179: Monitor | C179: B.3/230/05/2019 | D179: TRUE | E179: FALSE | F179: FALSE
A180: =A179+1 -> 179 | B180: Monitor | C180: B.3/230/08/2019 | D180: TRUE | E180: FALSE | F180: FALSE
A181: =A180+1 -> 180 | B181: Monitor | C181: B.3/230/106/2019 | D181: TRUE | E181: FALSE | F181: FALSE
A182: =A181+1 -> 181 | B182: Monitor | C182: B.3/230/111/2019 | D182: TRUE | E182: FALSE | F182: FALSE
A183: =A182+1 -> 182 | B183: Monitor | C183: B.3/230/112/2019 | D183: TRUE | E183: FALSE | F183: FALSE
A184: =A183+1 -> 183 | B184: Monitor | C184: B.3/230/113/2019 | D184: TRUE | E184: FALSE | F184: FALSE
A185: =A184+1 -> 184 | B185: Monitor | C185: B.3/230/115/2019 | D185: TRUE | E185: FALSE | F185: FALSE
A186: =A185+1 -> 185 | B186: Monitor | C186: B.3/230/121/2019 | D186: TRUE | E186: FALSE | F186: FALSE
A187: =A186+1 -> 186 | B187: Monitor | C187: B.3/230/123/2019 | D187: TRUE | E187: FALSE | F187: FALSE
A188: =A187+1 -> 187 | B188: Monitor | C188: B.3/230/135/2019 | D188: TRUE | E188: FALSE | F188: FALSE
A189: =A188+1 -> 188 | B189: Monitor | C189: B.3/230/141/2019 | D189: TRUE | E189: FALSE | F189: FALSE
... A1084: =A1083+1 -> 1083 | B1084: Monitor | C1084: MN/0474/2025 | D1084: TRUE | E1084: FALSE | F1084: FALSE
A1085: =A1084+1 -> 1084 | B1085: Monitor
A1086: =A1085+1 -> 1085 | B1086: Monitor
A1087: =A1086+1 -> 1086 | B1087: Monitor
A1088: =A1087+1 -> 1087 | B1088: Monitor
A1089: =A1088+1 -> 1088 | B1089: Monitor
A1090: =A1089+1 -> 1089 | B1090: Monitor
A1091: =A1090+1 -> 1090 | B1091: Monitor
A1092: =A1091+1 -> 1091 | B1092: Monitor
A1093: =A1092+1 -> 1092 | B1093: Monitor
A1094: =A1093+1 -> 1093 | B1094: Monitor
A1095: =A1094+1 -> 1094 | B1095: Monitor

Sheet KEYBOARD - NO INV
B1: NOMOR INVENTARIS TERAKHIR = KB/0323/2021
A3: NO | B3: NAMA ASET | C3: NO INVENTARIS | D3: STIKER TERTEMPEL | E3: STIKER BLM TERTEMPEL | F3: KETERANGAN | H3: KODE | I3: NOMOR | J3: TAHUN
A4: 1 | B4: Keyboard | C4: =H4&"/"&I4&"/"&J4 -> KB/0324/2025 | D4: TRUE | E4: FALSE | H4: KB | I4: 0324 | J4: 2025
A5: =A4+1 -> 2 | B5: Keyboard | C5: =H5&"/"&I5&"/"&J5 -> KB/0325/2025 | D5: TRUE | E5: FALSE | H5: KB | I5: 0325 | J5: 2025
A6: =A5+1 -> 3 | B6: Keyboard | C6: =H6&"/"&I6&"/"&J6 -> KB/0326/2025 | D6: TRUE | E6: FALSE | H6: KB | I6: 0326 | J6: 2025
A7: =A6+1 -> 4 | B7: Keyboard | C7: =H7&"/"&I7&"/"&J7 -> KB/0327/2025 | D7: TRUE | E7: FALSE | H7: KB | I7: 0327 | J7: 2025
A8: =A7+1 -> 5 | B8: Keyboard | C8: =H8&"/"&I8&"/"&J8 -> KB/0328/2025 | D8: TRUE | E8: FALSE | H8: KB | I8: 0328 | J8: 2025
A9: =A8+1 -> 6 | B9: Keyboard | C9: =H9&"/"&I9&"/"&J9 -> KB/0329/2025 | D9: TRUE | E9: FALSE | H9: KB | I9: 0329 | J9: 2025
A10: =A9+1 -> 7 | B10: Keyboard | C10: =H10&"/"&I10&"/"&J10 -> KB/0330/2025 | D10: TRUE | E10: FALSE | H10: KB | I10: 0330 | J10: 2025
A11: =A10+1 -> 8 | B11: Keyboard | C11: =H11&"/"&I11&"/"&J11 -> KB/0331/2025 | D11: TRUE | E11: FALSE | H11: KB | I11: 0331 | J11: 2025
A12: =A11+1 -> 9 | B12: Keyboard | C12: =H12&"/"&I12&"/"&J12 -> KB/0332/2025 | D12: TRUE | E12: FALSE | H12: KB | I12: 0332 | J12: 2025
A13: =A12+1 -> 10 | B13: Keyboard | C13: =H13&"/"&I13&"/"&J13 -> KB/0333/2025 | D13: TRUE | E13: FALSE | H13: KB | I13: 0333 | J13: 2025
A14: =A13+1 -> 11 | B14: Keyboard | C14: =H14&"/"&I14&"/"&J14 -> KB/0334/2025 | D14: TRUE | E14: FALSE | H14: KB | I14: 0334 | J14: 2025
A15: =A14+1 -> 12 | B15: Keyboard | C15: =H15&"/"&I15&"/"&J15 -> KB/0335/2025 | D15: TRUE | E15: FALSE | H15: KB | I15: 0335 | J15: 2025
A16: =A15+1 -> 13 | B16: Keyboard | C16: =H16&"/"&I16&"/"&J16 -> KB/0336/2025 | D16: TRUE | E16: FALSE | H16: KB | I16: 0336 | J16: 2025
... A153: =A152+1 -> 150 | B153: Keyboard | C153: =H153&"/"&I153&"/"&J153 -> KB/0473/2025 | D153: TRUE | E153: FALSE | H153: KB | I153: 0473 | J153: 2025
A154: =A153+1 -> 151 | B154: Keyboard | C154: =H154&"/"&I154&"/"&J154 -> KB/0474/2025 | D154: TRUE | E154: FALSE | H154: KB | I154: 0474 | J154: 2025 | K154: DITEMPEL MANAGEMENT
A155: =A154+1 -> 152 | B155: Keyboard | C155: =H155&"/"&I155&"/"&J155 -> KB/0475/2025 | D155: TRUE | E155: FALSE | H155: KB | I155: 0475 | J155: 2025
A156: =A155+1 -> 153 | B156: Keyboard | C156: =H156&"/"&I156&"/"&J156 -> KB/0476/2025 | D156: TRUE | E156: FALSE | H156: KB | I156: 0476 | J156: 2025
A157: =A156+1 -> 154 | B157: Keyboard | C157: =H157&"/"&I157&"/"&J157 -> KB/0477/2025 | D157: TRUE | E157: FALSE | H157: KB | I157: 0477 | J157: 2025
A158: =A157+1 -> 155 | B158: Keyboard | C158: =H158&"/"&I158&"/"&J158 -> KB/0478/2025 | D158: TRUE | E158: FALSE | H158: KB | I158: 0478 | J158: 2025
A159: =A158+1 -> 156 | B159: Keyboard | C159: =H159&"/"&I159&"/"&J159 -> KB/0479/2025 | D159: TRUE | E159: FALSE | H159: KB | I159: 0479 | J159: 2025
A160: =A159+1 -> 157 | B160: Keyboard | C160: =H160&"/"&I160&"/"&J160 -> KB/0480/2025 | D160: TRUE | E160: FALSE | H160: KB | I160: 0480 | J160: 2025
A161: =A160+1 -> 158 | B161: Keyboard | C161: =H161&"/"&I161&"/"&J161 -> KB/0481/2025 | D161: TRUE | E161: FALSE | H161: KB | I161: 0481 | J161: 2025
A162: =A161+1 -> 159 | B162: Keyboard | C162: =H162&"/"&I162&"/"&J162 -> KB/0482/2025 | D162: TRUE | E162: FALSE | F162: 45867 | H162: KB | I162: 0482 | J162: 2025
